<?xml version='1.0'?>

<robot name="badger" xmlns:xacro="http://www.ros.org/wiki/xacro">
  
  <xacro:include filename="inertial_macros.xacro"/>
  <xacro:include filename="badger_robot.gazebo.xacro"/>

    <material name="white">
        <color rgba="1 1 1 1" />
    </material>

    <material name="orange">
        <color rgba="1 0.3 0.1 1"/>
    </material>

    <material name="blue">
        <color rgba="0.2 0.2 1 1"/>
    </material>

    <material name="black">
        <color rgba="0 0 0 1"/>
    </material>

    <material name="red">
        <color rgba="1 0 0 1"/>
    </material>

    <link name="base_footprint"/>

    <joint name="base_joint" type="fixed">
        <parent link="base_footprint"/>
        <child link="base_link"/>
        <origin xyz="0 0 0.035"/>
    </joint>

    <link name="base_link">
        <visual>
          <origin xyz="0 0 0.035"/>
          <geometry>
              <box size="0.325 0.225 0.005"/>
          </geometry>
          <material name="white"/>
        </visual>
        <collision>
          <origin xyz="0.1625 0 0.0025"/>
          <geometry>
              <box size="0.325 0.225 0.005"/>
          </geometry>
        </collision>
        <xacro:inertial_box mass="15" x="0.325" y="0.225" z="0.005">
            <origin xyz="0.1625 0 0.0025" rpy="0 0 0"/>
        </xacro:inertial_box>
    </link>

    <gazebo reference="base_link">
        <material>Gazebo/White</material>
    </gazebo>

    <joint name="bl_wheel_joint" type="continuous">
        <parent link="base_link"/>
        <child link="bl_wheel"/>
        <origin xyz="-0.125 0.11 0" rpy="-${pi/2} 0 0" />
        <axis xyz="0 0 1"/>
    </joint>

    <link name="bl_wheel">
        <visual>
            <geometry>
                <cylinder radius="0.04" length="0.035"/>
            </geometry>
            <material name="blue"/>
        </visual>
        <collision>
            <geometry>
                <cylinder radius="0.04" length="0.035"/> 
            </geometry>
        </collision>
        <xacro:inertial_cylinder mass="10" length="0.035" radius="0.04">
            <origin xyz="0 0 0" rpy="0 0 0"/>
        </xacro:inertial_cylinder>
    </link>

    <gazebo reference="bl_wheel">
        <material>Gazebo/Blue</material>
    </gazebo>

    <joint name="br_wheel_joint" type="continuous">
      <parent link="base_link"/>
      <child link="br_wheel"/>
      <origin xyz="-0.125 -0.11 0" rpy="-${pi/2} 0 0" />
      <axis xyz="0 0 1"/>
    </joint>

    <link name="br_wheel">
      <visual>
          <geometry>
              <cylinder radius="0.04" length="0.035"/>
          </geometry>
          <material name="blue"/>
      </visual>
      <collision>
          <geometry>
              <cylinder radius="0.04" length="0.035"/> 
          </geometry>
      </collision>
      <xacro:inertial_cylinder mass="10" length="0.035" radius="0.04">
          <origin xyz="0 0 0" rpy="0 0 0"/>
      </xacro:inertial_cylinder>
    </link>

    <gazebo reference="br_wheel">
      <material>Gazebo/Blue</material>
    </gazebo>

    <joint name="fl_wheel_joint" type="fixed">
        <parent link="base_link"/>
        <child link="fl_wheel"/>
        <origin xyz="0.125 0.11 0" rpy="-${pi/2} 0 0" />
        <axis xyz="0 0 1"/>
    </joint>
  
    <link name="fl_wheel">
        <visual>
            <geometry>
                <cylinder radius="0.04" length="0.035"/>
            </geometry>
            <material name="black"/>
        </visual>
        <collision>
            <geometry>
                <cylinder radius="0.04" length="0.035"/> 
            </geometry>
        </collision>
        <xacro:inertial_cylinder mass="10" length="0.035" radius="0.04">
            <origin xyz="0 0 0" rpy="0 0 0"/>
        </xacro:inertial_cylinder>
    </link>
  
    <gazebo reference="fl_wheel">
        <material>Gazebo/Black</material>
    </gazebo>

    <joint name="fr_wheel_joint" type="fixed">
        <parent link="base_link"/>
        <child link="fr_wheel"/>
        <origin xyz="0.125 -0.11 0" rpy="-${pi/2} 0 0" />
        <axis xyz="0 0 1"/>
    </joint>
  
    <link name="fr_wheel">
        <visual>
            <geometry>
                <cylinder radius="0.04" length="0.035"/>
            </geometry>
            <material name="black"/>
        </visual>
        <collision>
            <geometry>
                <cylinder radius="0.04" length="0.035"/> 
            </geometry>
        </collision>
        <xacro:inertial_cylinder mass="10" length="0.035" radius="0.04">
            <origin xyz="0 0 0" rpy="0 0 0"/>
        </xacro:inertial_cylinder>
    </link>
  
    <gazebo reference="fr_wheel">
        <material>Gazebo/Black</material>
    </gazebo>
    
      <joint name="imu_joint" type="fixed">
    <parent link="base_link"/>
    <child link="imu_link"/>
    <origin xyz="-0.032 0 0.068" rpy="0 0 0"/>
  </joint>

  <link name="imu_link"/>

  <joint name="scan_joint" type="fixed">
    <parent link="base_link"/>
    <child link="base_scan"/>
    <origin xyz="-0.032 0 0.172" rpy="0 0 0"/>
  </joint>

  <link name="base_scan">
    <visual>
      <origin xyz="0.015 0 -0.0065" rpy="0 0 0"/>
      <geometry>
        <cylinder length="0.03" radius="0.08"/>
      </geometry>
      <material name="dark"/>
    </visual>

    <collision>
      <origin xyz="0.015 0 -0.0065" rpy="0 0 0"/>
      <geometry>
        <cylinder length="0.03" radius="0.03"/>
      </geometry>
    </collision>

    <inertial>
      <mass value="10" />
      <origin xyz="0 0 0" />
      <inertia ixx="0.001" ixy="0.0" ixz="0.0"
               iyy="0.001" iyz="0.0"
               izz="0.001" />
    </inertial>
  </link>
  
  <gazebo>
    <plugin name="object_controller" filename="libgazebo_ros_planar_move.so">
      <commandTopic>cmd_vel</commandTopic>
      <odometryTopic>odom</odometryTopic>
      <odometryFrame>odom</odometryFrame>
      <odometryRate>20.0</odometryRate>
      <robotBaseFrame>base_footprint</robotBaseFrame>
    </plugin>
  </gazebo>

</robot>
